# 第一章 Django 测试概述

您如何知道您编写的代码何时按预期工作？好吧，你来测试一下。但是怎么做呢？对于 web 应用程序，可以通过在 web 浏览器中手动调出应用程序的页面并验证它们是否正确来测试代码。这不仅仅是一个快速浏览，看看他们是否有正确的内容，因为你还必须确保，例如，所有的链接工作正常，任何形式的工作正常。正如您可以想象的那样，随着应用程序的发展超出了几个简单的页面，这种手动测试很快变得不可能依赖。对于任何非平凡的应用程序，自动化测试都是必不可少的。

Django 应用程序的自动测试利用了 Python 语言内置的基本测试支持：doctest 和单元测试。当您使用`manage.py startapp`创建一个新的 Django 应用程序时，其中一个生成的文件包含一个示例 doctest 和单元测试，用于跳转开始您自己的测试编写。在本章中，我们将开始研究测试 Django 应用程序。具体而言，我们将：

*   详细检查样本`tests.py`文件的内容，同时回顾 Python 测试支持的基础知识
*   请参阅如何使用 Django 实用程序运行`tests.py`中包含的测试
*   了解如何在测试成功和失败时解释测试的输出
*   查看测试时可以使用的各种命令行选项的效果

# 入门：创建新应用程序

让我们开始创建一个新的 Django 项目和应用程序。为了让我们在这本书中有一致的内容，让我们假设我们正在着手创建一个新的市场调研类型的网站。在这一点上，除了 Django 项目的一些名称和它将包含的至少一个应用程序之外，我们不需要对这个站点做太多的决定。由于`market_research`有点长，我们将其缩短为`marketr`作为项目名称。我们可以使用`django-admin.py`创建一个新的 Django 项目：

```
kmt@lbox:/dj_projects$ django-admin.py startproject marketr

```

然后，在新的`marketr`目录中，我们可以使用`manage.py`实用程序创建一个新的 Django 应用程序。我们的市场研究项目的核心应用程序之一是调查应用程序，因此我们将从创建它开始：

```
kmt@lbox:/dj_projects/marketr$ python manage.py startapp survey

```

现在我们有了 Django 项目和应用程序的基本框架：一个`settings.py`文件、一个`urls.py`文件、`manage.py`实用程序和一个`survey`目录，其中包含用于模型、视图和测试的`.py`文件。自动生成的模型和视图文件中没有任何实质内容，但在`tests.py`文件中有两个示例测试：一个单元测试和一个 doctest。我们将在下一步详细检查每一项。

# 了解样本单元测试

单元测试是`tests.py`中包含的第一个测试，它开始于：

```
""" 
This file demonstrates two different styles of tests (one doctest and one unittest). These will both pass when you run "manage.py test". 

Replace these with more appropriate tests for your application. 
"""

from django.test import TestCase 

class SimpleTest(TestCase): 
    def test_basic_addition(self): 
        """ 
        Tests that 1 + 1 always equals 2\. 
        """ 
        self.failUnlessEqual(1 + 1, 2) 
```

单元测试从`django.test`导入`TestCase`开始。`django.test.TestCase`类基于 Python 的`unittest.TestCase`，因此它提供了从底层 Python`unittest.TestCase`到测试 Django 应用程序有用的所有功能。这些对`unittest.TestCase`的 Django 扩展将在[第 3 章](03.html "Chapter 3. Testing 1, 2, 3: Basic Unit Testing")、*测试 1、2、3：基本单元测试*和[第 4 章](04.html "Chapter 4. Getting Fancier: Django Unit Test Extensions")、*变得更有趣：Django 单元测试扩展*中详细介绍。这里的示例单元测试实际上不需要任何这种支持，但无论如何，将示例测试用例建立在 Django 类的基础上并没有什么坏处。

然后，样本单元测试基于 Django 的`TestCase`声明了一个`SimpleTest`类，并在该类中定义了一个名为`test_basic_addition`的测试方法。该方法包含一条语句：

```
self.failUnlessEqual(1 + 1, 2)
```

正如您所期望的，该语句将导致测试用例报告失败，除非提供的两个参数相等。按照编码，我们希望测试能够成功。在本章后面，当我们开始实际运行测试时，我们将验证这一点。但是首先，让我们仔细看看样本 DOCTREST。

# 了解样本医生测试

样本`tests.py`的 doctest 部分为：

```
__test__ = {"doctest": """
Another way to test that 1 + 1 is equal to 2.

>>> 1 + 1 == 2
True
"""}
```

这看起来比单元测试的一半更神秘。对于示例 doctest，声明了一个特殊变量`__test__`。此变量设置为包含一个键`doctest`的字典。该键被设置为一个字符串值，该值类似于包含注释的 docstring，后跟一个类似于交互式 Python shell 会话的片段。

看起来像交互式 Python shell 会话的部分是构成 doctest 的部分。也就是说，在测试期间将执行以`>>>`开头的行（减去`>>>`前缀），并将生成的实际输出与以`>>>`开头的行下方的 doctest 中找到的预期输出进行比较。如果任何实际输出与预期输出不匹配，则测试失败。对于这个示例测试，我们希望在交互式 Python shell 会话中输入`1 + 1 == 2`将导致解释器生成输出`True`，因此，这个示例测试看起来同样应该通过。

请注意，doctest 不必使用这个特殊的`__test__`字典来定义。实际上，Python 的 doctest 测试运行程序在文件中找到的所有 docstring 中查找 doctest。在 Python 中，docstring 是一个字符串文字，它是模块、函数、类或方法定义中的第一条语句。有鉴于此，您可能希望在这个`tests.py`文件顶部的注释中找到的交互式 Python shell 会话的片段也可以作为 doctest 运行。一旦我们开始运行这些测试，这是另一件我们可以尝试的事情，我们将在下一步做。

# 运行样本测试

样本`tests.py`文件顶部的注释说明两个测试：`will both pass when you run "manage.py test"`。那么，让我们看看如果我们尝试这样做会发生什么：

```
kmt@lbox:/dj_projects/marketr$ python manage.py test 
Creating test database... 
Traceback (most recent call last): 
 File "manage.py", line 11, in <module> 
 execute_manager(settings) 
 File "/usr/lib/python2.5/site-packages/django/core/management/__init__.py", line 362, in execute_manager 
 utility.execute() 
 File "/usr/lib/python2.5/site-packages/django/core/management/__init__.py", line 303, in execute 
 self.fetch_command(subcommand).run_from_argv(self.argv) 
 File "/usr/lib/python2.5/site-packages/django/core/management/base.py", line 195, in run_from_argv 
 self.execute(*args, **options.__dict__) 
 File "/usr/lib/python2.5/site-packages/django/core/management/base.py", line 222, in execute 
 output = self.handle(*args, **options) 
 File "/usr/lib/python2.5/site-packages/django/core/management/commands/test.py", line 23, in handle 
 failures = test_runner(test_labels, verbosity=verbosity, interactive=interactive) 
 File "/usr/lib/python2.5/site-packages/django/test/simple.py", line 191, in run_tests 
 connection.creation.create_test_db(verbosity, autoclobber=not interactive) 
 File "/usr/lib/python2.5/site-packages/django/db/backends/creation.py", line 327, in create_test_db 
 test_database_name = self._create_test_db(verbosity, autoclobber) 
 File "/usr/lib/python2.5/site-packages/django/db/backends/creation.py", line 363, in _create_test_db 
 cursor = self.connection.cursor() 
 File "/usr/lib/python2.5/site-packages/django/db/backends/dummy/base.py", line 15, in complain 
 raise ImproperlyConfigured, "You haven't set the DATABASE_ENGINE setting yet." 
django.core.exceptions.ImproperlyConfigured: You haven't set the DATABASE_ENGINE setting yet.

```

哎呀，我们在这里似乎走在了前面。我们创建了新的 Django 项目和应用程序，但从未编辑设置文件以指定任何数据库信息。显然，为了运行测试，我们需要这样做。

但是测试会使用我们在`settings.py`中指定的生产数据库吗？这可能令人担忧，因为我们可能会在测试中编写一些我们不想对生产数据执行的代码。幸运的是，这不是问题。Django 测试运行程序为运行测试创建一个全新的数据库，在测试期间使用它，并在测试运行结束时删除它。该数据库的名称为`test_`后接`settings.py`中指定的`DATABASE_NAME`。因此，运行测试不会干扰生产数据。

为了运行示例`tests.py`文件，我们需要首先为`DATABASE_ENGINE`、`DATABASE_NAME`设置适当的值，以及我们在`settings.py`中使用的数据库可能需要的任何其他值。现在也是将我们的`survey`申请和`django.contrib.admin`添加到`INSTALLED_APPS`的好时机，因为我们在继续进行时将需要这两个。对`settings.py`进行这些更改后，`manage.py test`的效果会更好：

```
kmt@lbox:/dj_projects/marketr$ python manage.py test 
Creating test database... 
Creating table auth_permission 
Creating table auth_group 
Creating table auth_user 
Creating table auth_message 
Creating table django_content_type 
Creating table django_session 
Creating table django_site 
Creating table django_admin_log 
Installing index for auth.Permission model 
Installing index for auth.Message model 
Installing index for admin.LogEntry model 
................................... 
---------------------------------------------------------------------- 
Ran 35 tests in 2.012s 

OK 
Destroying test database...

```

看起来不错。但到底测试了什么？最后写着`Ran 35 tests`，所以运行的测试肯定比我们简单的`tests.py`文件中的两个测试要多。其他 33 项测试来自`settings.py`中默认列出的其他应用程序：身份验证、内容类型、会话和站点。这些 Django“contrib”应用程序附带自己的测试，默认情况下，`manage.py test`为`INSTALLED_APPS`中列出的所有应用程序运行测试。

### 注

请注意，如果您没有将`django.contrib.admin`添加到`settings.py`中的`INSTALLED_APPS`列表中，则`manage.py test`可能会报告一些测试失败。对于 Django 1.1，`django.contrib.auth`的一些测试依赖于`django.contrib.admin`也包含在`INSTALLED_APPS`中，以便通过测试。这种相互依赖性在将来可能会被修复，但目前最容易避免可能出现的错误的方法是从一开始就将`django.contrib.admin`包含在`INTALLED_APPS`中。无论如何，我们都希望尽快使用它。

可以只对某些应用程序运行测试。为此，请在命令行上指定应用程序名称。例如，要仅运行`survey`应用程序测试：

```
kmt@lbox:/dj_projects/marketr$ python manage.py test survey 
Creating test database... 
Creating table auth_permission 
Creating table auth_group 
Creating table auth_user 
Creating table auth_message 
Creating table django_content_type 
Creating table django_session 
Creating table django_site 
Creating table django_admin_log 
Installing index for auth.Permission model 
Installing index for auth.Message model 
Installing index for admin.LogEntry model 
.. 
---------------------------------------------------------------------- 
Ran 2 tests in 0.039s 

OK 
Destroying test database... 

```

在那里-`Ran 2 tests`看起来适合我们的样本`tests.py`文件。但是关于创建表和安装索引的所有消息呢？当这些应用程序的测试不运行时，为什么要创建这些应用程序的表？原因是，测试运行程序不知道将要测试的应用程序与`INSTALLED_APPS`中列出的其他将不测试的应用程序之间可能存在哪些依赖关系。

例如，我们的调查应用程序可能有一个与`django.contrib.auth User`模型具有`ForeignKey`的模型，调查应用程序的测试可能依赖于能够添加和查询`User`条目。如果测试运行程序忽略了为被排除在测试之外的应用程序创建表，那么这将不起作用。因此，测试运行程序为`INSTALLED_APPS`中列出的所有应用程序创建表，即使是那些不运行测试的应用程序。

我们现在知道了如何运行测试，如何将测试限制在我们感兴趣的应用程序上，以及成功的测试运行是什么样子的。但是，测试失败怎么办？在实际工作中，我们可能会遇到相当多的测试输出，因此最好确保我们在测试输出出现时理解它们。然后，在下一节中，我们将介绍一些故意破坏，以便我们可以探索失败的样子，并确保当我们遇到真实的失败时，我们将知道如何正确解释测试运行报告的内容。

# 故意破坏东西

让我们从介绍一个简单的失败开始。更改单元测试，以期望添加`1 + 1`将导致`3`而不是`2`。即将单元测试中的单语句改为：`self.failUnlessEqual(1 + 1, 3)`。

现在当我们运行测试时，我们将得到一个失败：

```
kmt@lbox:/dj_projects/marketr$ python manage.py test
Creating test database... 
Creating table auth_permission 
Creating table auth_group 
Creating table auth_user 
Creating table auth_message 
Creating table django_content_type 
Creating table django_session 
Creating table django_site 
Creating table django_admin_log 
Installing index for auth.Permission model
Installing index for auth.Message model 
Installing index for admin.LogEntry model 
...........................F.......
====================================================================== 
FAIL: test_basic_addition (survey.tests.SimpleTest) 
---------------------------------------------------------------------- 
Traceback (most recent call last): 
 File "/dj_projects/marketr/survey/tests.py", line 15, in test_basic_addition 
 self.failUnlessEqual(1 + 1, 3) 
AssertionError: 2 != 3 

---------------------------------------------------------------------- 
Ran 35 tests in 2.759s 

FAILED (failures=1) 
Destroying test database...

```

这看起来很简单。失败产生了一个输出块，从一行等号开始，然后是失败测试的细节。识别失败的方法以及包含它的类。有一个`Traceback`显示了产生故障的确切代码行，`AssertionError`显示了故障原因的详细信息。

注意等号上方的线，它包含一束点和一个`F`。这是什么意思？这是我们在前面的测试输出清单中忽略的一行。如果你现在回头看，你会发现在最后一条`Installing index`信息之后，总是有一条带有一些点的线。该行在测试运行时生成，打印内容取决于测试结果。`F`表示测试失败，dot 表示测试通过。当有足够的测试需要运行一段时间时，此实时进度更新有助于了解运行过程中的运行情况。

最后，在测试输出的末尾，我们看到的是`FAILED (failures=1)`，而不是之前看到的`OK`。任何测试失败都会使整个测试运行结果失败而不是成功。

接下来，让我们看看失败的 doctest 是什么样子。如果我们将单元测试恢复到其原始形式，并将 doctest 更改为期望 Python 解释器响应`True`到`1 + 1 == 3`，那么运行测试（这次仅将测试限制为`survey`应用程序）将产生以下输出：

```
kmt@lbox:/dj_projects/marketr$ python manage.py test survey 
Creating test database... 
Creating table auth_permission 
Creating table auth_group 
Creating table auth_user 
Creating table auth_message 
Creating table django_content_type 
Creating table django_session 
Creating table django_site 
Creating table django_admin_log 
Installing index for auth.Permission model 
Installing index for auth.Message model 
Installing index for admin.LogEntry model 
.F 
====================================================================== 
FAIL: Doctest: survey.tests.__test__.doctest 
---------------------------------------------------------------------- 
Traceback (most recent call last): 
 File "/usr/lib/python2.5/site-packages/django/test/_doctest.py", line 2180, in runTest 
 raise self.failureException(self.format_failure(new.getvalue())) 
AssertionError: Failed doctest test for survey.tests.__test__.doctest 
 File "/dj_projects/marketr/survey/tests.py", line unknown line number, in doctest 

---------------------------------------------------------------------- 
File "/dj_projects/marketr/survey/tests.py", line ?, in survey.tests.__test__.doctest 
Failed example: 
 1 + 1 == 3 
Expected: 
 True 
Got: 
 False 

---------------------------------------------------------------------- 
Ran 2 tests in 0.054s 

FAILED (failures=1) 
Destroying test database... 

```

与单元测试失败相比，失败的 doctest 的输出更加详细，解释起来也不那么直观。失败的 doctest 被标识为`survey.tests.__test__.doctest`-这意味着`survey/tests.py`文件中定义的`__test__`字典中的键`doctest`。输出的`Traceback`部分不像在单元测试用例中那样有用，因为`AssertionError`只是指出 doctest 失败。幸运的是，随后提供了导致故障的详细信息，您可以看到导致故障的行的内容、预期的输出以及执行故障行实际产生的输出。

但是，请注意，测试运行程序没有精确指出故障发生的`tests.py`内的行号。它在输出的不同部分报告`unknown line number`和`line ?`。这是 doctest 的一个普遍问题，还是作为`__test__`字典的一部分，这个特定 doctest 的定义方式的结果？我们可以通过在`tests.py`顶部的文档字符串中放置一个测试来回答这个问题。让我们将示例 doctest 恢复到其原始状态，并将文件顶部更改为如下所示：

```
""" 
This file demonstrates two different styles of tests (one doctest and one unittest). These will both pass when you run "manage.py test". 

Replace these with more appropriate tests for your application. 

>>> 1 + 1 == 3 
True
""" 
```

然后，当我们运行测试时，我们得到：

```
kmt@lbox:/dj_projects/marketr$ python manage.py test survey 
Creating test database... 
Creating table auth_permission 
Creating table auth_group 
Creating table auth_user 
Creating table auth_message 
Creating table django_content_type 
Creating table django_session 
Creating table django_site 
Creating table django_admin_log 
Installing index for auth.Permission model 
Installing index for auth.Message model 
Installing index for admin.LogEntry model 
.F. 
====================================================================== 
FAIL: Doctest: survey.tests 
---------------------------------------------------------------------- 
Traceback (most recent call last): 
 File "/usr/lib/python2.5/site-packages/django/test/_doctest.py", line 2180, in runTest 
 raise self.failureException(self.format_failure(new.getvalue())) 
AssertionError: Failed doctest test for survey.tests 
 File "/dj_projects/marketr/survey/tests.py", line 0, in tests 

---------------------------------------------------------------------- 
File "/dj_projects/marketr/survey/tests.py", line 7, in survey.tests 
Failed example: 
 1 + 1 == 3 
Expected: 
 True 
Got: 
 False 

---------------------------------------------------------------------- 
Ran 3 tests in 0.052s 

FAILED (failures=1) 
Destroying test database... 

```

这里提供了行号。`Traceback`部分显然标识了包含失败测试行的文档串开始的行上方的行（文档串开始于`line 1`而回溯报告`line 0`。详细的故障输出标识文件中导致故障的实际行，在本例中为`line 7`。

因此，无法精确定位行号是在`__test__`字典中定义 doctest 的副作用。虽然它在这里不会引起太大的问题，因为在我们的简单测试中，看到哪一行导致了问题并不重要，但在编写更多实质性的 doctest 放入`__test__`字典时，需要记住这一点。如果测试中有多条线路相同，且其中一条线路导致故障，则可能很难确定是哪条线路导致故障，因为故障输出无法确定故障发生的具体线路号。

到目前为止，我们在样本测试中引入的所有错误都涉及预期输出与实际结果不匹配。这些被报告为测试失败。除了测试失败之外，我们有时还会遇到测试错误。下面将描述这些。

# 测试错误与测试失败

为了了解测试错误是什么样子，让我们删除上一节介绍的失败的 doctest，并在我们的示例单元测试中引入一种不同类型的错误。我们假设不想测试`1 + 1`是否等于文字`2`，而是要测试它是否等于函数`sum_args`的结果，该函数应该返回其参数的和。但是我们会犯一个错误，忘记导入那个函数。所以将`self.failUnlessEqual`改为：

```
self.failUnlessEqual(1 + 1, sum_args(1, 1))
```

现在，当测试运行时，我们看到：

```
kmt@lbox:/dj_projects/marketr$ python manage.py test survey 
Creating test database... 
Creating table auth_permission 
Creating table auth_group 
Creating table auth_user 
Creating table auth_message 
Creating table django_content_type 
Creating table django_session 
Creating table django_site 
Creating table django_admin_log 
Installing index for auth.Permission model 
Installing index for auth.Message model 
Installing index for admin.LogEntry model 
E. 
====================================================================== 
ERROR: test_basic_addition (survey.tests.SimpleTest) 
---------------------------------------------------------------------- 
Traceback (most recent call last): 
 File "/dj_projects/marketr/survey/tests.py", line 15, in test_basic_addition 
 self.failUnlessEqual(1 + 1, sum_args(1, 1)) 
NameError: global name 'sum_args' is not defined 

---------------------------------------------------------------------- 
Ran 2 tests in 0.041s 

FAILED (errors=1) 
Destroying test database... 

```

由于没有导入`sum_args`，测试运行程序在到达可以将`1 + 1`与`sum_args`的返回值进行比较的点之前遇到了异常。在本例中，错误在测试本身，但如果`sum_args`中的代码是导致问题的原因，那么它仍然会被报告为错误，而不是失败。失败意味着实际结果与预期不符，而错误意味着在测试运行期间遇到了其他一些问题（异常）。错误可能意味着测试本身有错误，但不一定意味着有错误。

请注意，doctest 中发生的类似错误报告为失败，而不是错误。例如，我们可以将 doctest`1 + 1`行更改为：

```
>>> 1 + 1 == sum_args(1, 1) 
```

如果我们随后运行测试，输出将为：

```
kmt@lbox:/dj_projects/marketr$ python manage.py test survey 
Creating test database... 
Creating table auth_permission 
Creating table auth_group 
Creating table auth_user 
Creating table auth_message 
Creating table django_content_type 
Creating table django_session 
Creating table django_site 
Creating table django_admin_log 
Installing index for auth.Permission model 
Installing index for auth.Message model 
Installing index for admin.LogEntry model 
EF 
====================================================================== 
ERROR: test_basic_addition (survey.tests.SimpleTest) 
---------------------------------------------------------------------- 
Traceback (most recent call last): 
 File "/dj_projects/marketr/survey/tests.py", line 15, in test_basic_addition 
 self.failUnlessEqual(1 + 1, sum_args(1, 1)) 
NameError: global name 'sum_args' is not defined 

====================================================================== 
FAIL: Doctest: survey.tests.__test__.doctest 
---------------------------------------------------------------------- 
Traceback (most recent call last): 
 File "/usr/lib/python2.5/site-packages/django/test/_doctest.py", line 2180, in runTest 
 raise self.failureException(self.format_failure(new.getvalue())) 
AssertionError: Failed doctest test for survey.tests.__test__.doctest 
 File "/dj_projects/marketr/survey/tests.py", line unknown line number, in doctest 

---------------------------------------------------------------------- 
File "/dj_projects/marketr/survey/tests.py", line ?, in survey.tests.__test__.doctest 
Failed example: 
 1 + 1 == sum_args(1, 1) 
Exception raised: 
 Traceback (most recent call last): 
 File "/usr/lib/python2.5/site-packages/django/test/_doctest.py", line 1267, in __run 
 compileflags, 1) in test.globs 
 File "<doctest survey.tests.__test__.doctest[0]>", line 1, in <module> 
 1 + 1 == sum_args(1, 1) 
 NameError: name 'sum_args' is not defined 

---------------------------------------------------------------------- 
Ran 2 tests in 0.044s 

FAILED (failures=1, errors=1) 
Destroying test database... 

```

因此，单元测试的错误与失败的区别不一定适用于 doctest。因此，如果您的测试包括 doctest，那么最后打印的失败和错误计数摘要并不一定反映有多少测试产生了意外的结果（单元测试失败计数）或有一些其他错误（单元测试错误计数）。但是，在任何情况下，都不希望出现故障或错误。最终目标是两者都为零，因此，如果两者之间的差异有时有点模糊，那也没什么大不了的。不过，了解在什么情况下报告一个而不是另一个可能是有用的。

我们现在已经了解了如何运行测试，以及总体成功和一些失败和错误的结果。接下来，我们将研究`manage.py test`命令支持的各种命令行选项。

# 运行测试的命令行选项

除了在命令行上指定要测试的确切应用程序外，还有哪些其他选项可用于控制`manage.py`测试的行为？最简单的方法是尝试使用选项`--help`：运行该命令

```
kmt@lbox:/dj_projects/marketr$ python manage.py test --help
Usage: manage.py test [options] [appname ...]

Runs the test suite for the specified applications, or the entire site if no apps are specified.

Options:
 -v VERBOSITY, --verbosity=VERBOSITY
 Verbosity level; 0=minimal output, 1=normal output,
 2=all output
 --settings=SETTINGS   The Python path to a settings module, e.g.
 "myproject.settings.main". If this isn't provided, the
 DJANGO_SETTINGS_MODULE environment variable will 
 be used.
 --pythonpath=PYTHONPATH
 A directory to add to the Python path, e.g.
 "/home/djangoprojects/myproject".
 --traceback           Print traceback on exception
 --noinput             Tells Django to NOT prompt the user for input of 
 any kind.
 --version             show program's version number and exit
 -h, --help            show this help message and exit

```

让我们依次考虑每一个（除了我们已经看到它做了什么）：

## 冗长

详细度是介于`0`和`2`之间的数值。它控制测试产生的输出量。默认值为`1`，因此我们目前看到的输出对应于指定`-v 1`或`--verbosity=1`。将 verbosity 设置为`0`将抑制所有有关创建测试数据库和表的消息，但不会抑制摘要、失败或错误信息。如果我们纠正上一节中介绍的最后一次 doctest 失败，并重新运行指定为`-v0`的测试，我们将看到：

```
kmt@lbox:/dj_projects/marketr$ python manage.py test survey -v0 
====================================================================== 
ERROR: test_basic_addition (survey.tests.SimpleTest) 
---------------------------------------------------------------------- 
Traceback (most recent call last): 
 File "/dj_projects/marketr/survey/tests.py", line 15, in test_basic_addition 
 self.failUnlessEqual(1 + 1, sum_args(1, 1)) 
NameError: global name 'sum_args' is not defined 

---------------------------------------------------------------------- 
Ran 2 tests in 0.008s 

FAILED (errors=1) 

```

将 verbosity 设置为`2`会产生更多的输出。如果我们修复此剩余错误，并将详细性设置为其最高级别来运行测试，我们将看到：

```
kmt@lbox:/dj_projects/marketr$ python manage.py test survey --verbosity=2 
Creating test database... 
Processing auth.Permission model 
Creating table auth_permission 
Processing auth.Group model 
Creating table auth_group 
 **[...more snipped...]**

**Creating many-to-many tables for auth.Group model** 
**Creating many-to-many tables for auth.User model** 
**Running post-sync handlers for application auth** 
**Adding permission 'auth | permission | Can add permission'** 
**Adding permission 'auth | permission | Can change permission'** 
 ****[...more snipped...]**

**No custom SQL for auth.Permission model** 
**No custom SQL for auth.Group model** 

**[...more snipped...]**
 ****Installing index for auth.Permission model** 
**Installing index for auth.Message model** 
**Installing index for admin.LogEntry model** 
**Loading 'initial_data' fixtures...** 
**Checking '/usr/lib/python2.5/site-packages/django/contrib/auth/fixtures' for fixtures...** 
**Trying '/usr/lib/python2.5/site-packages/django/contrib/auth/fixtures' for initial_data.xml fixture 'initial_data'...** 
**No xml fixture 'initial_data' in '/usr/lib/python2.5/site-packages/django/contrib/auth/fixtures'.** 

**[....much more snipped...]**
**No fixtures found.** 
**test_basic_addition (survey.tests.SimpleTest) ... ok** 
**Doctest: survey.tests.__test__.doctest ... ok** 

**----------------------------------------------------------------------** 
**Ran 2 tests in 0.004s** 

**OK** 
**Destroying test database...****** 
```

 ****正如您所看到的，在这种详细程度上，命令以极其详细的方式报告了它为设置测试数据库所做的一切。除了我们前面看到的创建数据库表和索引之外，我们现在看到数据库设置阶段包括：

1.  正在运行`post-syncdb`信号处理器。例如，`django.contrib.auth`应用程序使用此信号在安装每个应用程序时自动为模型添加权限。因此，当`INSTALLED_APPS`中列出的每个应用程序发送`post-syncdb`信号时，您会看到有关权限创建的消息。
2.  为数据库中创建的每个模型运行自定义 SQL。根据输出，它看起来不像`INSTALLED_APPS`中的任何应用程序使用自定义 SQL。
3.  装载`initial_data`固定装置。初始数据装置是一种用一些常量数据自动预填充数据库的方法。我们在`INSTALLED_APPS`中列出的所有应用程序都没有使用此功能，但在测试运行程序查找初始数据装置时，会产生大量输出，这些装置可以在几个不同的名称下找到。对于检查的每个可能的文件以及是否找到任何内容，都有消息。如果我们在测试运行程序找到初始数据固定装置时遇到麻烦，那么这个输出可能会在某个时候派上用场（我们将在[第 3 章](03.html "Chapter 3. Testing 1, 2, 3: Basic Unit Testing")中详细介绍固定装置），但现在这个输出不是很有趣。

一旦测试运行程序完成初始化数据库，它就开始运行测试。在详细级别`2`中，我们前面看到的点、Fs 和 Es 行在运行时被每个测试的更详细报告所取代。打印测试名称，后跟三个点，然后打印测试结果，测试结果将为`ok`、`ERROR`或`FAIL`。如果有任何错误或失败，将在测试运行结束时打印有关错误或失败原因的详细信息。因此，当您在详细程度设置为`2`的情况下观察长时间的测试运行时，您将能够看到哪些测试遇到了问题，但在运行完成之前，您将无法获得出现问题的原因的详细信息。

## 设置

您可以将设置选项传递给`test`命令，以指定要使用的设置文件，而不是项目默认文件。例如，如果您希望使用与您通常使用的数据库不同的数据库来运行测试（无论是为了测试的速度还是为了验证代码在不同的数据库上正确运行），这都会很方便。

注意：此选项的帮助文本说明，如果未在命令行上指定设置选项，`DJANGO_SETTINGS_MODULE`环境变量将用于定位设置文件。这仅在通过`django-admin.py`实用程序运行`test`命令时才准确。使用`manage.py test`时，`manage.py`实用程序负责设置此环境变量，以指定当前目录中的`settings.py`文件。

## 蟒蛇

此选项允许您在测试运行期间使用的Python 路径中附加一个目录。它主要用于使用`django-admin.py`时，通常需要将项目路径添加到标准 Python 路径中。`manage.py`实用程序负责将项目路径添加到 Python 路径，因此在使用`manage.py test`时通常不需要此选项。

## 回溯

`test`命令实际上没有使用此选项。它作为所有`django-admin.py`（和`manage.py`命令支持的默认选项之一被继承，但`test`命令从不检查它。因此，您可以指定它，但它将无效。

## 无输入

此选项会导致测试运行程序不提示用户输入，这会引发一个问题：测试运行程序何时需要用户输入？到目前为止，我们还没有遇到这种情况。如果已存在具有测试数据库名称的数据库，则测试运行程序会在创建测试数据库期间提示输入。例如，如果在测试运行期间点击*Ctrl*+*C*，测试数据库可能不会被破坏，并且在下次尝试运行测试时可能会遇到如下消息：

```
kmt@lbox:/dj_projects/marketr$ python manage.py test 
Creating test database... 
Got an error creating the test database: (1007, "Can't create database 'test_marketr'; database exists") 
Type 'yes' if you would like to try deleting the test database 'test_marketr', or 'no' to cancel: 

```

如果在命令行上传递了`--noinput`，则不会打印提示，测试运行程序将继续进行，就像用户在响应中输入了“是”一样。如果您希望从无人参与的脚本运行测试，并确保脚本在等待永远不会输入的用户输入时不会挂起，这将非常有用。

## 版本

此选项报告正在使用的 Django 版本，然后退出。因此，当将`--version`与`manage.py`或`django-admin.py`一起使用时，实际上不需要指定子命令，例如`test`。事实上，由于 Django 处理命令选项的方式存在缺陷，在编写本书时，如果您同时指定了`--version`和子命令，则该版本将打印两次。这可能会在某个时候得到解决。

# 总结

Django 测试的概述现在已经完成。在本章中，我们：

*   详细查看了创建新 Django 应用程序时生成的示例`tests.py`文件
*   了解了如何运行提供的示例测试
*   尝试在测试中引入有意的错误，以便查看和理解测试失败或遇到错误时提供的信息
*   最后，我们检查了所有可能与`manage.py test`一起使用的命令行选项

在下一章中，我们将继续以这些知识为基础，深入探讨博士学位。****